 * Serving Flask app "main" (lazy loading)
 * Environment: production
   WARNING: This is a development server. Do not use it in a production deployment.
   Use a production WSGI server instead.
 * Debug mode: off
 * Running on http://0.0.0.0:8045/ (Press CTRL+C to quit)
[2021-06-04 16:47:29,561] ERROR in app: Exception on /add_data [POST]
Traceback (most recent call last):
  File "/home/ubuntu/.local/lib/python3.8/site-packages/flask/app.py", line 2447, in wsgi_app
    response = self.full_dispatch_request()
  File "/home/ubuntu/.local/lib/python3.8/site-packages/flask/app.py", line 1952, in full_dispatch_request
    rv = self.handle_user_exception(e)
  File "/home/ubuntu/.local/lib/python3.8/site-packages/flask/app.py", line 1821, in handle_user_exception
    reraise(exc_type, exc_value, tb)
  File "/home/ubuntu/.local/lib/python3.8/site-packages/flask/_compat.py", line 39, in reraise
    raise value
  File "/home/ubuntu/.local/lib/python3.8/site-packages/flask/app.py", line 1950, in full_dispatch_request
    rv = self.dispatch_request()
  File "/home/ubuntu/.local/lib/python3.8/site-packages/flask/app.py", line 1936, in dispatch_request
    return self.view_functions[rule.endpoint](**req.view_args)
  File "main.py", line 83, in add_data
    os.chdir('../../../../servico_recepcao_dados')
FileNotFoundError: [Errno 2] No such file or directory: '../../../../servico_recepcao_dados'
187.110.233.41 - - [04/Jun/2021 16:47:29] "[35m[1mPOST /add_data HTTP/1.1[0m" 500 -
 * Serving Flask app "main" (lazy loading)
 * Environment: production
   WARNING: This is a development server. Do not use it in a production deployment.
   Use a production WSGI server instead.
 * Debug mode: off
 * Running on http://0.0.0.0:8045/ (Press CTRL+C to quit)
187.110.233.41 - - [04/Jun/2021 17:02:37] "[37mPOST /add_data HTTP/1.1[0m" 200 -
[2021-06-04 17:19:35,072] ERROR in app: Exception on /add_data [POST]
Traceback (most recent call last):
  File "/home/ubuntu/.local/lib/python3.8/site-packages/flask/app.py", line 2447, in wsgi_app
    response = self.full_dispatch_request()
  File "/home/ubuntu/.local/lib/python3.8/site-packages/flask/app.py", line 1952, in full_dispatch_request
    rv = self.handle_user_exception(e)
  File "/home/ubuntu/.local/lib/python3.8/site-packages/flask/app.py", line 1821, in handle_user_exception
    reraise(exc_type, exc_value, tb)
  File "/home/ubuntu/.local/lib/python3.8/site-packages/flask/_compat.py", line 39, in reraise
    raise value
  File "/home/ubuntu/.local/lib/python3.8/site-packages/flask/app.py", line 1950, in full_dispatch_request
    rv = self.dispatch_request()
  File "/home/ubuntu/.local/lib/python3.8/site-packages/flask/app.py", line 1936, in dispatch_request
    return self.view_functions[rule.endpoint](**req.view_args)
  File "main.py", line 33, in add_data
    obj_id = data['deviceId']
TypeError: list indices must be integers or slices, not str
179.183.144.159 - - [04/Jun/2021 17:19:35] "[35m[1mPOST /add_data HTTP/1.1[0m" 500 -
[2021-06-04 17:20:27,912] ERROR in app: Exception on /add_data [POST]
Traceback (most recent call last):
  File "/home/ubuntu/.local/lib/python3.8/site-packages/flask/app.py", line 2447, in wsgi_app
    response = self.full_dispatch_request()
  File "/home/ubuntu/.local/lib/python3.8/site-packages/flask/app.py", line 1952, in full_dispatch_request
    rv = self.handle_user_exception(e)
  File "/home/ubuntu/.local/lib/python3.8/site-packages/flask/app.py", line 1821, in handle_user_exception
    reraise(exc_type, exc_value, tb)
  File "/home/ubuntu/.local/lib/python3.8/site-packages/flask/_compat.py", line 39, in reraise
    raise value
  File "/home/ubuntu/.local/lib/python3.8/site-packages/flask/app.py", line 1950, in full_dispatch_request
    rv = self.dispatch_request()
  File "/home/ubuntu/.local/lib/python3.8/site-packages/flask/app.py", line 1936, in dispatch_request
    return self.view_functions[rule.endpoint](**req.view_args)
  File "main.py", line 33, in add_data
    obj_id = data['deviceId']
TypeError: list indices must be integers or slices, not str
179.183.144.159 - - [04/Jun/2021 17:20:27] "[35m[1mPOST /add_data HTTP/1.1[0m" 500 -
[2021-06-04 17:21:35,264] ERROR in app: Exception on /add_data [POST]
Traceback (most recent call last):
  File "/home/ubuntu/.local/lib/python3.8/site-packages/flask/app.py", line 2447, in wsgi_app
    response = self.full_dispatch_request()
  File "/home/ubuntu/.local/lib/python3.8/site-packages/flask/app.py", line 1952, in full_dispatch_request
    rv = self.handle_user_exception(e)
  File "/home/ubuntu/.local/lib/python3.8/site-packages/flask/app.py", line 1821, in handle_user_exception
    reraise(exc_type, exc_value, tb)
  File "/home/ubuntu/.local/lib/python3.8/site-packages/flask/_compat.py", line 39, in reraise
    raise value
  File "/home/ubuntu/.local/lib/python3.8/site-packages/flask/app.py", line 1950, in full_dispatch_request
    rv = self.dispatch_request()
  File "/home/ubuntu/.local/lib/python3.8/site-packages/flask/app.py", line 1936, in dispatch_request
    return self.view_functions[rule.endpoint](**req.view_args)
  File "main.py", line 33, in add_data
    obj_id = data['deviceId']
TypeError: list indices must be integers or slices, not str
179.183.144.159 - - [04/Jun/2021 17:21:35] "[35m[1mPOST /add_data HTTP/1.1[0m" 500 -
179.183.144.159 - - [04/Jun/2021 17:22:24] "[31m[1mPOST /add_data HTTP/1.1[0m" 400 -
[2021-06-04 17:22:34,640] ERROR in app: Exception on /add_data [POST]
Traceback (most recent call last):
  File "/home/ubuntu/.local/lib/python3.8/site-packages/flask/app.py", line 2447, in wsgi_app
    response = self.full_dispatch_request()
  File "/home/ubuntu/.local/lib/python3.8/site-packages/flask/app.py", line 1952, in full_dispatch_request
    rv = self.handle_user_exception(e)
  File "/home/ubuntu/.local/lib/python3.8/site-packages/flask/app.py", line 1821, in handle_user_exception
    reraise(exc_type, exc_value, tb)
  File "/home/ubuntu/.local/lib/python3.8/site-packages/flask/_compat.py", line 39, in reraise
    raise value
  File "/home/ubuntu/.local/lib/python3.8/site-packages/flask/app.py", line 1950, in full_dispatch_request
    rv = self.dispatch_request()
  File "/home/ubuntu/.local/lib/python3.8/site-packages/flask/app.py", line 1936, in dispatch_request
    return self.view_functions[rule.endpoint](**req.view_args)
  File "main.py", line 33, in add_data
    obj_id = data['deviceId']
TypeError: list indices must be integers or slices, not str
179.183.144.159 - - [04/Jun/2021 17:22:34] "[35m[1mPOST /add_data HTTP/1.1[0m" 500 -
[2021-06-04 17:23:58,552] ERROR in app: Exception on /add_data [POST]
Traceback (most recent call last):
  File "/home/ubuntu/.local/lib/python3.8/site-packages/flask/app.py", line 2447, in wsgi_app
    response = self.full_dispatch_request()
  File "/home/ubuntu/.local/lib/python3.8/site-packages/flask/app.py", line 1952, in full_dispatch_request
    rv = self.handle_user_exception(e)
  File "/home/ubuntu/.local/lib/python3.8/site-packages/flask/app.py", line 1821, in handle_user_exception
    reraise(exc_type, exc_value, tb)
  File "/home/ubuntu/.local/lib/python3.8/site-packages/flask/_compat.py", line 39, in reraise
    raise value
  File "/home/ubuntu/.local/lib/python3.8/site-packages/flask/app.py", line 1950, in full_dispatch_request
    rv = self.dispatch_request()
  File "/home/ubuntu/.local/lib/python3.8/site-packages/flask/app.py", line 1936, in dispatch_request
    return self.view_functions[rule.endpoint](**req.view_args)
  File "main.py", line 33, in add_data
    obj_id = data['deviceId']
TypeError: list indices must be integers or slices, not str
179.183.144.159 - - [04/Jun/2021 17:23:58] "[35m[1mPOST /add_data HTTP/1.1[0m" 500 -
[2021-06-04 17:28:18,324] ERROR in app: Exception on /add_data [POST]
Traceback (most recent call last):
  File "/home/ubuntu/.local/lib/python3.8/site-packages/flask/app.py", line 2447, in wsgi_app
    response = self.full_dispatch_request()
  File "/home/ubuntu/.local/lib/python3.8/site-packages/flask/app.py", line 1952, in full_dispatch_request
    rv = self.handle_user_exception(e)
  File "/home/ubuntu/.local/lib/python3.8/site-packages/flask/app.py", line 1821, in handle_user_exception
    reraise(exc_type, exc_value, tb)
  File "/home/ubuntu/.local/lib/python3.8/site-packages/flask/_compat.py", line 39, in reraise
    raise value
  File "/home/ubuntu/.local/lib/python3.8/site-packages/flask/app.py", line 1950, in full_dispatch_request
    rv = self.dispatch_request()
  File "/home/ubuntu/.local/lib/python3.8/site-packages/flask/app.py", line 1936, in dispatch_request
    return self.view_functions[rule.endpoint](**req.view_args)
  File "main.py", line 33, in add_data
    obj_id = data['deviceId']
TypeError: list indices must be integers or slices, not str
179.183.144.159 - - [04/Jun/2021 17:28:18] "[35m[1mPOST /add_data HTTP/1.1[0m" 500 -
[2021-06-04 17:37:03,188] ERROR in app: Exception on /add_data [POST]
Traceback (most recent call last):
  File "/home/ubuntu/.local/lib/python3.8/site-packages/flask/app.py", line 2447, in wsgi_app
    response = self.full_dispatch_request()
  File "/home/ubuntu/.local/lib/python3.8/site-packages/flask/app.py", line 1952, in full_dispatch_request
    rv = self.handle_user_exception(e)
  File "/home/ubuntu/.local/lib/python3.8/site-packages/flask/app.py", line 1821, in handle_user_exception
    reraise(exc_type, exc_value, tb)
  File "/home/ubuntu/.local/lib/python3.8/site-packages/flask/_compat.py", line 39, in reraise
    raise value
  File "/home/ubuntu/.local/lib/python3.8/site-packages/flask/app.py", line 1950, in full_dispatch_request
    rv = self.dispatch_request()
  File "/home/ubuntu/.local/lib/python3.8/site-packages/flask/app.py", line 1936, in dispatch_request
    return self.view_functions[rule.endpoint](**req.view_args)
  File "main.py", line 33, in add_data
    obj_id = data['deviceId']
TypeError: list indices must be integers or slices, not str
179.183.144.159 - - [04/Jun/2021 17:37:03] "[35m[1mPOST /add_data HTTP/1.1[0m" 500 -
179.183.144.159 - - [04/Jun/2021 17:42:23] "[31m[1mGET /add_data HTTP/1.1[0m" 405 -
[2021-06-04 17:42:36,708] ERROR in app: Exception on /add_data [POST]
Traceback (most recent call last):
  File "/home/ubuntu/.local/lib/python3.8/site-packages/flask/app.py", line 2447, in wsgi_app
    response = self.full_dispatch_request()
  File "/home/ubuntu/.local/lib/python3.8/site-packages/flask/app.py", line 1952, in full_dispatch_request
    rv = self.handle_user_exception(e)
  File "/home/ubuntu/.local/lib/python3.8/site-packages/flask/app.py", line 1821, in handle_user_exception
    reraise(exc_type, exc_value, tb)
  File "/home/ubuntu/.local/lib/python3.8/site-packages/flask/_compat.py", line 39, in reraise
    raise value
  File "/home/ubuntu/.local/lib/python3.8/site-packages/flask/app.py", line 1950, in full_dispatch_request
    rv = self.dispatch_request()
  File "/home/ubuntu/.local/lib/python3.8/site-packages/flask/app.py", line 1936, in dispatch_request
    return self.view_functions[rule.endpoint](**req.view_args)
  File "main.py", line 33, in add_data
    obj_id = data['deviceId']
TypeError: list indices must be integers or slices, not str
179.183.144.159 - - [04/Jun/2021 17:42:36] "[35m[1mPOST /add_data HTTP/1.1[0m" 500 -
[2021-06-04 17:49:10,257] ERROR in app: Exception on /add_data [POST]
Traceback (most recent call last):
  File "/home/ubuntu/.local/lib/python3.8/site-packages/flask/app.py", line 2447, in wsgi_app
    response = self.full_dispatch_request()
  File "/home/ubuntu/.local/lib/python3.8/site-packages/flask/app.py", line 1952, in full_dispatch_request
    rv = self.handle_user_exception(e)
  File "/home/ubuntu/.local/lib/python3.8/site-packages/flask/app.py", line 1821, in handle_user_exception
    reraise(exc_type, exc_value, tb)
  File "/home/ubuntu/.local/lib/python3.8/site-packages/flask/_compat.py", line 39, in reraise
    raise value
  File "/home/ubuntu/.local/lib/python3.8/site-packages/flask/app.py", line 1950, in full_dispatch_request
    rv = self.dispatch_request()
  File "/home/ubuntu/.local/lib/python3.8/site-packages/flask/app.py", line 1936, in dispatch_request
    return self.view_functions[rule.endpoint](**req.view_args)
  File "main.py", line 33, in add_data
    obj_id = data['deviceId']
TypeError: list indices must be integers or slices, not str
187.110.233.41 - - [04/Jun/2021 17:49:10] "[35m[1mPOST /add_data HTTP/1.1[0m" 500 -
